2025-03-17 20:12:23,786 [INFO] USER:atharvamukul_mujumda s3_resource.py:40:validate_bucket_name LOG: Starting validating bucket name 'syndicate-education-platform-custom-sandbox-artifacts-6675'
2025-03-17 20:12:23,786 [INFO] USER:atharvamukul_mujumda s3_resource.py:73:validate_bucket_name LOG: Finished validating bucket name 'syndicate-education-platform-custom-sandbox-artifacts-6675'
2025-03-17 20:12:23,786 [INFO] USER:atharvamukul_mujumda helper.py:525:convert LOG: Stripping run_id:JAP-11,run_type:stm,type:user,user_id:605734c9 from "," a bit..
2025-03-17 20:12:23,787 [INFO] USER:atharvamukul_mujumda helper.py:529:convert LOG: Converting: run_id:JAP-11,run_type:stm,type:user,user_id:605734c9 to dict..
2025-03-17 20:12:23,803 [INFO] USER:atharvamukul_mujumda helper.py:541:convert LOG: Converted to such a dict: {'run_id': 'JAP-11', 'run_type': 'stm', 'type': 'user', 'user_id': '605734c9'}
2025-03-17 20:12:25,707 [WARNING] USER:atharvamukul_mujumda generator.py:76:generate_configuration_files LOG: The config_path property is not specified. The working directory is used
2025-03-17 20:12:25,709 [WARNING] USER:atharvamukul_mujumda generator.py:93:generate_configuration_files LOG: The "project_path" property is not specified. The working directory will be used as a project path. To change the path, edit the syndicate.yml by path C:\Users\atharvamukul_mujumda\Desktop\AWS_Course\task07\.syndicate-config-dev
2025-03-17 20:12:25,717 [INFO] USER:atharvamukul_mujumda generator.py:155:generate_configuration_files LOG: Syndicate initialization has been completed. 
Set SDCT_CONF:
Unix: export SDCT_CONF="C:\Users\atharvamukul_mujumda\Desktop\AWS_Course\task07\.syndicate-config-dev"
Windows: setx SDCT_CONF C:\Users\atharvamukul_mujumda\Desktop\AWS_Course\task07\.syndicate-config-dev
2025-03-17 20:12:25,721 [INFO] USER:atharvamukul_mujumda helper.py:330:timed LOG: Stage config, elapsed time: 0:00:01.917133
2025-03-17 20:12:55,709 [INFO] USER:atharvamukul_mujumda handlers.py:106:syndicate LOG: Configuration used: C:\Users\atharvamukul_mujumda\Desktop\AWS_Course\.syndicate-config-dev
2025-03-17 20:12:55,712 [ERROR] USER:atharvamukul_mujumda decorators.py:136:wrapper LOG: sdct.conf does not exist inside C:\Users\atharvamukul_mujumda\Desktop\AWS_Course\.syndicate-config-dev folder
2025-03-17 20:12:55,723 [ERROR] USER:atharvamukul_mujumda decorators.py:137:wrapper LOG: Traceback (most recent call last):
  File "C:\Users\atharvamukul_mujumda\AppData\Local\Programs\Python\Python313\Lib\site-packages\syndicate\core\decorators.py", line 134, in wrapper
    return_code = func(*args, **kwargs)
  File "C:\Users\atharvamukul_mujumda\AppData\Local\Programs\Python\Python313\Lib\site-packages\syndicate\core\handlers.py", line 107, in syndicate
    initialize_connection()
    ~~~~~~~~~~~~~~~~~~~~~^^
  File "C:\Users\atharvamukul_mujumda\AppData\Local\Programs\Python\Python313\Lib\site-packages\syndicate\core\__init__.py", line 106, in initialize_connection
    CONFIG = ConfigHolder(CONF_PATH)
  File "C:\Users\atharvamukul_mujumda\AppData\Local\Programs\Python\Python313\Lib\site-packages\syndicate\core\conf\processor.py", line 63, in __init__
    self._init_conf_config(dir_path=dir_path)
    ~~~~~~~~~~~~~~~~~~~~~~^^^^^^^^^^^^^^^^^^^
  File "C:\Users\atharvamukul_mujumda\AppData\Local\Programs\Python\Python313\Lib\site-packages\syndicate\core\conf\processor.py", line 92, in _init_conf_config
    raise AssertionError(
        'sdct.conf does not exist inside %s folder' % dir_path)
AssertionError: sdct.conf does not exist inside C:\Users\atharvamukul_mujumda\Desktop\AWS_Course\.syndicate-config-dev folder
Traceback (most recent call last):
  File "C:\Users\atharvamukul_mujumda\AppData\Local\Programs\Python\Python313\Lib\site-packages\syndicate\core\decorators.py", line 134, in wrapper
    return_code = func(*args, **kwargs)
  File "C:\Users\atharvamukul_mujumda\AppData\Local\Programs\Python\Python313\Lib\site-packages\syndicate\core\handlers.py", line 107, in syndicate
    initialize_connection()
    ~~~~~~~~~~~~~~~~~~~~~^^
  File "C:\Users\atharvamukul_mujumda\AppData\Local\Programs\Python\Python313\Lib\site-packages\syndicate\core\__init__.py", line 106, in initialize_connection
    CONFIG = ConfigHolder(CONF_PATH)
  File "C:\Users\atharvamukul_mujumda\AppData\Local\Programs\Python\Python313\Lib\site-packages\syndicate\core\conf\processor.py", line 63, in __init__
    self._init_conf_config(dir_path=dir_path)
    ~~~~~~~~~~~~~~~~~~~~~~^^^^^^^^^^^^^^^^^^^
  File "C:\Users\atharvamukul_mujumda\AppData\Local\Programs\Python\Python313\Lib\site-packages\syndicate\core\conf\processor.py", line 92, in _init_conf_config
    raise AssertionError(
        'sdct.conf does not exist inside %s folder' % dir_path)
AssertionError: sdct.conf does not exist inside C:\Users\atharvamukul_mujumda\Desktop\AWS_Course\.syndicate-config-dev folder
